Workbook

Sheet RESUMEN CHART

Sheet resumen
D1: FECHA | E1: 45263 | Q1: DIFERENCIAS
A3: TIPO DE CAMBIO CCL | B3: 1450 | C3: % | D3: LOCAL | E3: SB | F3: SB LETNA
A4: BONOS GUBERNAMENTALES | B4: =SUM(D4:F4) -> 7845975.6 | C4: =+B4/$B$12 -> 0.68158614 | D4: =+D65 -> 91380.523 | E4: 3183784.4 | F4: 4570810.7 | G4: 4,570,810.65 | H4: $3,183,784.40
A5: ACCIONES/OPCIONES/fondos acciones | B5: =SUM(D5:F5) -> 0 | C5: =+B5/$B$12 -> 0 | D5: 0 | I5: 0
A6: LIQUIDEZ | B6: =SUM(D6:F6) -> 297162.52 | C6: =+B6/$B$12 -> 0.025814744 | D6: =+D43 -> 297162.52 | I6: 874410.1
A7: hsbc MIAMI | B7: =SUM(D7:F7) -> 474789.31 | C7: =+B7/$B$12 -> 0.041245325 | D7: 474789.31 | I7: 0
A8: FONDOS /ETF/comodities | B8: =SUM(D8:F8) -> 0 | C8: =+B8/$B$12 -> 0 | D8: 0 | I8: 0
A9: HIPOTECAS | B9: =SUM(D9:F9) -> 660 | C9: =+B9/$B$12 -> 5.7334725e-05 | D9: =+CARTERA!D652 -> 660 | H9: 10904.91 | I9: 95800
A10: INMUEBLES/INCLUYE TRACKER | B10: =SUM(D10:F10) -> 2892761.1 | C10: =+B10/$B$12 -> 0.25129646 | D10: =143288*1.1+2735144.28896578 -> 2892761.1 | E10: 0 | F10: 0 | I10: 2735144.3
B11: =SUM(D11:E11) -> 0 | C11: =+B11/$B$12 -> 0
B12: =SUM(B4:B11) -> 11511348 | C12: =SUM(C4:C11) -> 1 | D12: =SUM(D4:D11) -> 3756753.4 | E12: =SUM(E4:E10) -> 3183784.4 | F12: =SUM(F4:F10) -> 4570810.7
A13: AÑO 2001 | B13: =+#REF!*1000 -> #REF!
A14: DIFERENCIA | B14: =+B12-B13 -> #REF!
G15: 246421.1
G16: 523211.46
G17: =+G15+G16 -> 769632.56
V23: =+H152+H141 -> 120752.59 | W23: 0 | X23: =+J152+J141 -> 95458.831 | Y23: =+K152+K141 -> 23029.09 | Z23: =+L152+L141 -> 2264.67
V34: =+V23+H163 -> 131815.37 | W34: =+W23+I163 -> 1 | X34: =+X23+J163 -> 99614.907 | Y34: =+Y23+K163 -> 30958.79 | Z34: =+Z23+L163 -> 1241.67
A35: RESUMEN EFECTIVO EN MONEDA EXTRANJERA | D35: =+CARTERA!C19 -> 235474.66
F36: NO CONSIDERADO EN EL CUADRO
A39: subtotal | D39: =SUM(D35:D38) -> 235474.66
A40: PLAZO FIJOS EN PESOS+FONDOS | D40: =+CARTERA!C20 -> 89447394
A41: COHEN CAUCION/MARIA | D41: 0
A42: INVERSIONES SMITH BARNEY | D42: 0
A43: TOTAL | D43: =+D39+(D40+D41)/B3+D42 -> 297162.52
V45: =+V34+H174 -> 22425.866
A46: total dolares | W46: =+W34+I174 -> 2 | X46: =+X34+J174 -> 43938.096 | Y46: =+Y34+K174 -> -12112.8 | Z46: =+Z34+L174 -> -9399.43
A48: POSICION ACTUAL AL 31/01/16 | J48: Nombre de la Especie | K48: Cantidad | L48: Precio | M48: Importe
A49: Especie | B49: Cantidad Total | C49: Cotizacion | D49: Valor de Mercado | G49: BONOS EN DOLARES | I49: COTIZACION AFUERA | J49: 00007 ALUAR ALUMINIO ARG. S.AI.I.C. | K49: 20,174.0000000 | L49: 9470 | M49: 191,047.78
A50: BONOS EN DOLARES | C50: COTIZACION AFUERA | D50: DOLARES | E50: PESOS | J50: 00251 COMERCIAL DEL PLATA | K50: 4,600.0000000 | L50: 3300 | M50: 15,180.00
J51: 00457 PAMPA ENERGIA S.A. | K51: 15,000.0000000 | L51: 12750 | M51: 191,250.00
J52: 00633 IRSA "B" | K52: 2,000.0000000 | L52: 14950 | M52: 29,900.00
G53: DICEEXT | H53: 200000 | I53: 1.41 | J53: 00804 PETROBRAS ENERGIA S.A. | K53: 18,352.0000000 | L53: 8600 | M53: 157,827.20
C54: 1.6 | F54: =+E54/$B$3 -> 0 | G54: PARA | H54: 270000 | I54: 0.55 | J54: 00807 TELECOM S.A. | K54: 3,900.0000000 | L54: 45000 | M54: 175,500.00 | V54: =+V45+H183 -> 26237.109
C55: 0.65 | F55: =+E55/$B$3 -> 0 | G55: PAA0 | H55: 20000 | I55: 0.55 | J55: 00839 SIDERAR -A- 1 VOTO | K55: 4,485.0000000 | L55: 7900 | M55: 35,431.50 | Y55: =+Y46+K183 -> -12112.8 | Z55: =+Z46+L183 -> -9399.43
C56: 0.65 | F56: =+E56/$B$3 -> 0 | G56: DICY | H56: 150000 | I56: 1.41 | J56: 30031 PETROLERA PAMPA S.A. ORD. 1 VOTO $ ESC. | K56: 1,362.0000000 | L56: 32450 | M56: 44,196.90
C57: 1.6 | F57: =+E57/$B$3 -> 0 | G57: GJ17 | H57: 100000 | I57: 1 | M57: _________________________
A58: BONOS EN DOLARES | C58: 1.1 | D58: 0 | F58: =+E58/$B$3 -> 0 | L58: ACCIONES | M58: 840,333.38
D59: =SUM(D51:D58) -> 0 | E59: =SUM(E51:E58) -> 0 | J59: 02405 NF18 - BONOS GARANT. DECRETO 1579/02 $ | K59: 243,990.0000000 | L59: 127500 | M59: 311,087.25
G60: TOTAL RESUMEN COHEN $ | J60: 05445 BONOS REP.ARG. A LA PAR USD 2010/2038 | K60: 20,000.0000000 | L60: 880000 | M60: 176,000.00
...

Sheet UVA
A1: UVA
A2: FECHA | B2: Valor | C2: Columna1 | D2: 45170 | E2: 12,7 | G2: 2024 | H2: - | I2: Variación | K2: 2023 | L2: - | M2: Variación
A3: 45139 | B3: 292.58 | I3: porcentual | M3: porcentual | O3: UF010 | S3: 0.06
A4: 45140 | B4: 293.13 | I4: mes | M4: mes | O4: CONCEPTO | P4: FECHA | Q4: importes | R4: en UVAs | S4: intereses | U4: HABER
A5: 45141 | B5: 293.68 | I5: anterior | M5: anterior
A6: 45142 | B6: 294.23 | G6: Enero | I6: 0.206 | K6: Enero | M6: 0.06 | O6: Alquiler agosto 2023 | P6: 45148 | Q6: 155000 | R6: =+Q6/VLOOKUP(P6,TablaUVA[#All],2) -> 520.88584 | S6: =+R6*$S$3*($P$31-P6)/360 -> 22.918977 | U6: 0
A7: 45143 | B7: 294.78 | G7: Febrero | I7: 0.132 | K7: Febrero | M7: 0.066 | O7: BBVA DEBITO | P7: 45164 | Q7: =-U7 -> -160000 | R7: =+Q7/VLOOKUP(P7,TablaUVA[#All],2) -> -521.2915 | S7: =+R7*$S$3*($P$31-P7)/360 -> -21.546715 | U7: 160000
A8: 45144 | B8: 294.78 | G8: Marzo | I8: 0.11 | K8: Marzo | M8: 0.077 | O8: BBVA DEBITO | P8: 45166 | Q8: =-U8 -> -90000 | R8: =+Q8/VLOOKUP(P8,TablaUVA[#All],2) -> -293.22647 | S8: =+R8*$S$3*($P$31-P8)/360 -> -12.022285 | U8: 90000
A9: 45145 | B9: 294.78 | G9: Abril | I9: 0.088 | K9: Abril | M9: 0.084 | O9: BBVA DEBITO | P9: 45171 | Q9: =-U9 -> -63000 | R9: =+Q9/VLOOKUP(P9,TablaUVA[#All],2) -> -202.44216 | S9: =+R9*$S$3*($P$31-P9)/360 -> -8.1314267 | U9: 63000
A10: 45146 | B10: 296.45 | G10: Mayo | I10: 0.042 | K10: Mayo | M10: 0.078 | O10: Alquiler septiembre 2023 | P10: 45179 | Q10: 155000 | R10: =+Q10/VLOOKUP(P10,TablaUVA[#All],2) -> 491.25254 | S10: =+R10*$S$3*($P$31-P10)/360 -> 19.076973 | U10: 0
A11: 45147 | B11: 297.01 | G11: Junio | I11: 0.046 | K11: Junio | M11: 0.06 | O11: Alquiler octubre 2023 | P11: 45209 | Q11: 155000 | R11: =+Q11/VLOOKUP(P11,TablaUVA[#All],2) -> 441.26858 | S11: =+R11*$S$3*($P$31-P11)/360 -> 14.929587 | U11: 0
A12: 45148 | B12: 297.57 | G12: Julio | I12: 0.04 | K12: Julio | M12: 0.063 | O12: BBVA DEBITO | P12: 45231 | Q12: =-U12 -> -165000 | R12: =+Q12/VLOOKUP(P12,TablaUVA[#All],2) -> -431.41766 | S12: =+R12*$S$3*($P$31-P12)/360 -> -13.014433 | U12: 165000
A13: 45149 | B13: 298.13 | G13: Agosto | I13: 0.042 | K13: Agosto | M13: 0.124 | O13: Alquiler noviembre 2023 | P13: 45240 | Q13: 213000 | R13: =+Q13/VLOOKUP(P13,TablaUVA[#All],2) -> 537.93312 | S13: =+R13*$S$3*($P$31-P13)/360 -> 15.42075 | U13: 0
A14: 45150 | B14: 298.69 | G14: Septiembre | I14: 0.035 | K14: Septiembre | M14: 0.127 | O14: BBVA DEBITO | P14: 45264 | Q14: =-U14 -> -103000 | R14: =+Q14/VLOOKUP(P14,TablaUVA[#All],2) -> -243.59096 | S14: =+R14*$S$3*($P$31-P14)/360 -> -6.0085769 | U14: 103000
A15: 45151 | B15: 298.69 | G15: Octubre | I15: 0.027 | K15: Octubre | M15: 0.083 | O15: Alquiler diciembre 2023 | P15: 45270 | Q15: 213000 | R15: =+Q15/VLOOKUP(P15,TablaUVA[#All],2) -> 495.7639 | S15: =+R15*$S$3*($P$31-P15)/360 -> 11.733079 | U15: 0
A16: 45152 | B16: 298.69 | G16: Noviembre | I16: 0.027 | K16: Noviembre | M16: 0.128 | O16: BBVA DEBITO | P16: 45290 | Q16: =-U16 -> -120000 | R16: =+Q16/VLOOKUP(P16,TablaUVA[#All],2) -> -258.95555 | S16: =+R16*$S$3*($P$31-P16)/360 -> -5.2654294 | U16: 120000
A17: 45153 | B17: 300.38 | G17: Diciembre | I17: 0.03 | K17: Diciembre | M17: 0.255 | O17: BBVA DEBITO | P17: 45296 | Q17: =-U17 -> -150000 | R17: =+Q17/VLOOKUP(P17,TablaUVA[#All],2) -> -316.23553 | S17: =+R17*$S$3*($P$31-P17)/360 -> -6.113887 | U17: 150000
A18: 45154 | B18: 300.94 | O18: Alquiler enero 2024 | P18: 45301 | Q18: 213000 | R18: =+Q18/VLOOKUP(P18,TablaUVA[#All],2) -> 440.41022 | S18: =+R18*$S$3*($P$31-P18)/360 -> 8.1475891 | U18: 0
A19: 45155 | B19: 301.54 | K19: 2025 | L19: - | M19: Variación | O19: TRANSFERENCIA adelanto EXPENSAS | P19: 45321 | Q19: 110523.54 | R19: =+Q19/VLOOKUP(P19,TablaUVA[#All],2) -> 201.49409 | S19: =+R19*$S$3*($P$31-P19)/360 -> 3.0559937
A20: 45156 | B20: 302.13 | M20: porcentual | O20: Alquiler FEBRERO 2024 | P20: 45332 | Q20: 364000 | R20: =+Q20/VLOOKUP(P20,TablaUVA[#All],2) -> 612.21744 | S20: =+R20*$S$3*($P$31-P20)/360 -> 8.1628992 | U20: 0
A21: 45157 | B21: 302.73 | M21: mes | O21: BBVA DEBITO | P21: 45345 | Q21: -75000 | R21: =+Q21/VLOOKUP(P21,TablaUVA[#All],2) -> -115.38284 | S21: =+R21*$S$3*($P$31-P21)/360 -> -1.2884417 | U21: 200000
A22: 45158 | B22: 302.73 | M22: anterior | O22: BBVA DEBITO | P22: 45352 | Q22: =-U21 -> -200000 | R22: =+Q22/VLOOKUP(P22,TablaUVA[#All],2) -> -294.08305 | S22: =+R22*$S$3*($P$31-P22)/360 -> -2.9408305 | U22: 0
A23: 45159 | B23: 302.73 | K23: Enero | M23: 0.022 | O23: Alquiler MARZO 2024 | P23: 45361 | Q23: 364000 | R23: =+Q23/VLOOKUP(P23,TablaUVA[#All],2) -> 508.2805 | S23: =+R23*$S$3*($P$31-P23)/360 -> 4.3203843 | U23: 100000
A24: 45160 | B24: 302.73 | K24: Febrero | M24: 0.024 | O24: BBVA DEBITO | P24: 45363 | Q24: =-U23 -> -100000 | R24: =+Q24/VLOOKUP(P24,TablaUVA[#All],2) -> -136.95816 | S24: =+R24*$S$3*($P$31-P24)/360 -> -1.1184916 | U24: 60000
A25: 45161 | B25: 305.12 | K25: Marzo | M25: 0.037 | O25: BBVA DEBITO | P25: 45367 | Q25: =-U24 -> -60000 | R25: =+Q25/VLOOKUP(P25,TablaUVA[#All],2) -> -80.079011 | S25: =+R25*$S$3*($P$31-P25)/360 -> -0.60059258
K26: Abril | M26: 0.028 | O26: TRANSFERENCIA adelanto EXPENSAS | P26: 45372 | Q26: 125000 | R26: =+Q26/VLOOKUP(P26,TablaUVA[#All],2) -> 163.52695 | S26: =+R26*$S$3*($P$31-P26)/360 -> 1.0901797
A27: 45162 | B27: 305.72 | K27: Mayo | M27: 0.015 | O27: Alquiler MARZO 2024 | P27: 45392 | Q27: 364000 | R27: =+Q27/VLOOKUP(P27,TablaUVA[#All],2) -> 439.58698 | S27: =+R27*$S$3*($P$31-P27)/360 -> 1.4652899
A28: 45163 | B28: 306.33 | K28: Junio | M28: 0.016 | O28: BBVA DEBITO | P28: 45394 | Q28: -860000 | R28: =+Q28/VLOOKUP(P28,TablaUVA[#All],2) -> -1030.3103 | S28: =+R28*$S$3*($P$31-P28)/360 -> -3.0909309
A29: 45164 | B29: 306.93 | K29: Julio | M29: =+M28 -> 0.016 | O29: total nominales historicos | Q29: =SUM(Q6:Q28) -> 285523.54 | R29: =SUM(R6:R28) -> 928.64698 | S29: =SUM(S6:S28) -> 29.179661
A30: 45165 | B30: 306.93 | K30: Agosto | M30: =+M29 -> 0.016
A31: 45166 | B31: 306.93 | K31: Septiembre | M31: =+M30 -> 0.016 | O31: DEUDA EN PESOS AL | P31: 45412 | R31: =+R29*VLOOKUP(P31,TablaUVA[#All],2) -> 826950.85 | S31: =+S29*VLOOKUP(P31,TablaUVA[#All],2) -> 25984.196
A32: 45167 | B32: 308.75 | K32: Octubre | M32: =+M31 -> 0.016
A33: 45168 | B33: 309.36 | K33: Noviembre | M33: =+M32 -> 0.016
A34: 45169 | B34: 309.97 | C34: =(+TablaUVA[[#This Row],[Valor]]-B3)/B3 -> 0.059436735 | K34: Diciembre | M34: =+M33 -> 0.016
A35: 45170 | B35: 310.58 | S35: 45488
A36: 45171 | B36: 311.2 | O36: FECHA | P36: DEPOSITADO | Q36: ACOBRAR | R36: VTO. | S36: DIAS | T36: TASA | U36: BANCO | V36: intereses | W36: UVA INICIO | X36: UVA VTO. | Y36: UVA DEPOS
A37: 45172 | B37: 311.2 | O37: 45306 | P37: 193200 | Q37: =+P37*(1+T37) -> 421789.74 | R37: =+O37+S37 -> 45488 | S37: =+$S$35-O37 -> 182 | T37: =+(+X37*(1+0.01/365*S37))/W37-1 -> 1.1831767 | V37: =+Q37-P37 -> 228589.74 | W37: =VLOOKUP(O37,TablaUVA[#All],2) -> 489.31 | X37: =VLOOKUP($S$35,TablaUVA[#All],2) -> 1062.95 | Y37: 4272.7665
A38: 45173 | B38: 311.2 | O38: 45307 | P38: 95900 | Q38: =+P38*(1+T38*S38/365) -> 150962.49 | R38: =+O38+S38 -> 45488 | S38: =+$S$35-O38 -> 181 | T38: =+(+X38*(1+0.01/365*S38))/W38-1 -> 1.157848 | V38: =+Q38-P38 -> 55062.492 | W38: =VLOOKUP(O38,TablaUVA[#All],2) -> 495.04 | X38: =VLOOKUP($S$35,TablaUVA[#All],2) -> 1062.95 | Y38: 1335.7042
A39: 45174 | B39: 313.04 | O39: 45310 | P39: 115000 | Q39: =+P39*(1+T39*S39/365) -> 177292.04 | R39: =+O39+S39 -> 45488 | S39: =+$S$35-O39 -> 178 | T39: =+(+X39*(1+0.01/365*S39))/W39-1 -> 1.1107276 | V39: =+Q39-P39 -> 62292.038 | W39: =VLOOKUP(O39,TablaUVA[#All],2) -> 506.05 | X39: =VLOOKUP($S$35,TablaUVA[#All],2) -> 1062.95 | Y39: 485.8986
A40: 45175 | B40: 313.66 | O40: 45315 | P40: 98600 | Q40: =+P40*(1+T40*S40/365) -> 146947.61 | R40: =+O40+S40 -> 45488 | S40: =+$S$35-O40 -> 173 | T40: =+(+X40*(1+0.01/365*S40))/W40-1 -> 1.0345343 | V40: =+Q40-P40 -> 48347.614 | W40: =VLOOKUP(O40,TablaUVA[#All],2) -> 524.93 | X40: =VLOOKUP($S$35,TablaUVA[#All],2) -> 1062.95 | Y40: 341.28357
...

Sheet CARTERA
A1: AGREGAR UNOS
C3: 58291 | J3: 90
A4: CERA | C4: 0
A5: miami | C5: 0 | J5: 90
A6: CAJA DE AHORRO | C6: =720+62565.63 -> 63285.63
A7: caja | C7: 0
A8: FONDO REATRIACION/PFIJO | C8: =+C47 -> 0
A9: SUBTOTAL | C9: =SUM(C3:C8) -> 121576.63 | F9: =+C9+resumen!H1951 -> 295205.78
A10: caja de ahorro ITAU | C10: 22463.01
A11: unicreidt | C11: 16686
C12: 53340
A13: kate Personal | C13: =2000+5000+1000+500 -> 8500
A14: depto via albertini | B14: 143288.48 | C14: 0
A15: CAJA | C15: 705.66 | G15: =SUM(G16:G18) -> 4065.01
A16: LIBRAS | C16: =1*50+15*20+1*10+3*5 -> 375 | F16: =SUM(#REF!) -> #REF! | G16: 3046.88
A17: TOTAL DOLARES | C17: =+C9 -> 121576.63 | G17: 960.63
A18: TOTAL EUROS | B18: 1.12 | C18: =SUM(C10:C15) -> 101694.67 | G18: 57.5
C19: =+(C17+C18*B18) -> 235474.66 | G19: 37912
A20: TOTAL LIQUIDO PESOS | C20: =+C624 -> 89447394 | G20: 180
C21: =SUM(C23:C30) -> 674000 | F21: =SUM(C23:C30) -> 674000 | G21: =+F24+#REF! -> #REF! | H21: =141000+41000+24000 -> 206000
A22: FECHA | B22: DEPOSITADO | C22: ACOBRAR | D22: VTO. | E22: DIAS | F22: TASA | G22: BANCO | J22: 90
A23: 45883 | B23: 31076.77 | C23: 30000 | D23: =+E23+A23 -> 45976 | E23: 93 | F23: =+C23*4.375%/2 -> 656.25 | G23: Invetna | H23: 15-05-34 -Coupon Rate 4.375%; Matures 05/15/2034; CUSIP 91282CKQ3 | J23: 90
A24: 45547 | B24: 216000 | C24: 216000 | D24: 45976 | E24: 184 | F24: =+C24*4.375%/2 -> 4725 | G24: Invetna | H24: 15-05-34 -Coupon Rate 4.375%; Matures 05/15/2034; CUSIP 91282CKQ3 | I24: =+F24*2/B24 -> 0.04375
B25: 53000 | C25: 53000 | D25: 45976 | E25: 184 | F25: =+C25*4.375%/2 -> 1159.375 | G25: HSBC MIAMI | H25: 31-05-28 -UNITED STATES TREAS NTS 4,375% 05/31/28 B/E DTD 05/31/23 1ST CPN DTE 11/30/23 CPN PMT SEMI ANNUAL ON MAY 31 AND NOV 30 | J25: 90
A26: 45701 | B26: 100000 | C26: 100000 | D26: 45976 | E26: 166 | F26: =+C26*4.375%/2 -> 2187.5 | G26: sb Personal | H26: 15-05-34 -Coupon Rate 4.375%; Matures 05/15/2034; CUSIP 91282CKQ3 | J26: 90
A27: 45713 | B27: 51002.93 | C27: 52000 | D27: 45989 | E27: 180 | F27: 1997.07 | G27: HSBC MIAMI | H27: LETRAS DEL TESORO
B28: 125000 | C28: 125000 | D28: 45991 | E28: 184 | F28: =+C28*4.875%/2 -> 3046.875 | G28: HSBC MIAMI | H28: 31-5-26 -UNITED STATES TREAS NTS 4.875% 05/31/26 B/E DTD 05/31/24 1ST CPN DTE 11/30/24 CPN PMT SEMI ANNUAL ON MAY 31 AND NOV 30
A29: 45519 | B29: 53000 | C29: 53000 | D29: 45991 | E29: 183 | F29: =+C29*3.625%/2 -> 960.625 | G29: HSBC MIAMI | H29: 15-05-34 -UNITED STATES TREAS NTS 3.625% 05/31/28 B/E DTD 05/31/23 1ST CPN DTE 11/30/23 CPN PMT SEMI ANNUAL ON MAY 31 AND NOV 30
A30: 45810 | B30: 45000 | C30: 45000 | D30: 45991 | E30: 183 | F30: =+C30*4.125%/2 -> 928.125 | G30: sb Personal | H30: 30-11-09 -Coupon Rate 4.125%; Matures 11/30/2029; CUSIP 91282CMA6 | J30: 90
A31: 45679 | B31: 57000 | C31: 57000 | D31: 46008 | E31: 329 | F31: =+C31*4.25%/2 -> 1211.25 | G31: HSBC MIAMI | H31: 30-6-29 -UNITED STATES TREAS NTS 4.250% 06/30/29 B/E DTD 06/30/24 1ST CPN DTE 12/31/24 CPN PMT SEMI ANNUAL ON JUN 30 AND DEC 31 | I31: CADA 6 MESES | J31: 90
A32: 45838 | B32: 165000 | C32: 165000 | D32: =+A32+E32 -> 46021 | E32: 183 | F32: =+C32*4.25%/2 -> 3506.25 | G32: sb Personal | H32: 30-06-29 -Coupon Rate 4.250%; Matures 06/30/2029; CUSIP 91282CKX8 | J32: 37
A33: 45858 | B33: 140000 | C33: =+B33 -> 140000 | D33: =+A33+E33 -> 46042 | E33: 184 | F33: =+C33*7.125%/2 -> 4987.5 | G33: Invetna | H33: 20-01-37 -Coupon Rate 7.125%; Matures 01/20/2037; CUSIP 105756BK5, COUPON PAYABLE SEMI-ANNUALLY ON JANUARY AND JULY 20th | I33: =+F33*2/B33 -> 0.07125 | J33: 37
A34: 45858 | B34: =21000+125000 -> 146000 | C34: =+B34 -> 146000 | D34: =+A34+E34 -> 46042 | E34: 184 | F34: =+C34*7.125%/2 -> 5201.25 | G34: sb Personal | H34: 20-01-37 -Coupon Rate 7.125%; Matures 01/20/2037; CUSIP 105756BK5, COUPON PAYABLE SEMI-ANNUALLY ON JANUARY AND JULY 20th | J34: 90
A35: 45890 | B35: 25614.11 | C35: 26000 | D35: =+A35+E35 -> 46053 | E35: 163 | F35: =+C35-B35 -> 385.89 | G35: HSBC MIAMI | H35: LETRAS DEL TESORO | J35: 90
A36: 45870 | B36: =36000+33000 -> 69000 | C36: =+B36 -> 69000 | D36: =+E36+A36 -> 46054 | E36: 184 | F36: =+C36*3.65%/2 -> 1259.25 | G36: sb Personal | H36: 01-0835 -COUPON 3,65% SEMESTRE 1/2 Y 1/8 VTO 1/8/2035. - Symbol / CUSIP / ISIN: - T6025AAC8-IT0005631590 | J36: 90
A37: 45884 | B37: 50000 | C37: 50000 | D37: =+A37+E37 -> 46068 | E37: 184 | F37: 1000 | G37: HSBC MIAMI | H37: 15-02-34 -UNITED STATES TREAS NTS 4.000% 02/15/34 B/E DTD 02/15/24 1ST CPN DTE 08/15/24 CPN PMT SEMI ANNUAL ON FEB 15 AND AUG 15 | I37: 45000
A38: 45884 | B38: =206000+35000 -> 241000 | C38: =+B38 -> 241000 | D38: =+A38+E38 -> 46068 | E38: 184 | F38: =+C38*4%/2 -> 4820 | G38: sb Personal | H38: 15-02-34 -Coupon Rate 4.000%; Matures 02/15/2034; CUSIP 91282CJZ5
A39: 45638 | B39: 30305.83 | C39: 37000 | D39: 47529 | E39: 0 | G39: HSBC MIAMI | H39: 15-02-30 -ZERO CPN UNITED STATES TREAS SEC STRIPPED INT PMT STRIP INT OF 30-YR BOND 5.375 DUE 0.000% 02/15/30 B/E DTD 02/15/01 | I39: CADA 6 MESES
A40: 45808 | B40: 23760.35 | C40: 36000 | D40: 49171 | E40: 0 | G40: HSBC MIAMI | H40: 15-08-34 -ZERO CPN UNITED STATES TREAS SEC STRIPPED INT PMT STRIP INT OF 30-YR BOND 4.50% DUE 02-15-2036 INT RATE 0.000% MATURITY 08/15/2034 DATED 02/15/2006 BOOK ENTRY ONLY ZERO CPN BD SUBJ TO FED TAX
B42: =SUBTOTAL(109,B23:B40) -> 1621760 | C42: =SUBTOTAL(109,C23:C40) -> 1641000 | E42: =MEDIAN(E29:E37) -> 184 | F42: =SUM(F23:F40) -> 38032.21
...

Sheet POR VTO.
A11: Etiquetas de fila | B11: Suma de ACOBRAR
A12: 45964 | B12: 3602793.5
A13: 45965 | B13: 3156535.2
A14: 45966 | B14: 3266257.6
A15: 45968 | B15: 3113321.6
A16: 45971 | B16: 4181926
A17: 45972 | B17: 3150703.3
A18: 45973 | B18: 3149828.1
A19: 45974 | B19: 3145158.1
A20: 45975 | B20: 3045445.2
A21: 45978 | B21: 3077511.3
A22: 45979 | B22: 3079573.5
A23: 45980 | B23: 3460294.9
... A41: 46034 | B41: 1041356.2
A42: Total general | B42: 92288676
B52: 1534
B53: -150
B54: =+B52+B53 -> 1384
B55: -700
B56: =+B54+B55 -> 684

Sheet PF ANTERIORES $
A1: Fecha | B1: Depositado | C1: A Cobrar | D1: Fecha Vto. | E1: Dias | F1: Tasa
A2: 34774 | B2: 600 | C2: =B2+(B2*F2/365*E2)*1 -> 632.68997 | D2: =A2+E2 -> 34810 | E2: 36 | F2: 0.5524 | G2: BID
A3: 34774 | B3: 849 | C3: =B3+(B3*F3/365*E3)*1 -> 895.25631 | D3: =A3+E3 -> 34810 | E3: 36 | F3: 0.5524 | G3: BID
A4: 34768 | B4: 1440 | C4: =B4+(B4*F4/365*E4)*1 -> 1521.2752 | D4: =A4+E4 -> 34810 | E4: 42 | F4: 0.4905 | G4: BID
A5: 34775 | B5: 522 | C5: =B5+(B5*F5/365*E5)*1 -> 549.63025 | D5: =A5+E5 -> 34810 | E5: 35 | F5: 0.552 | G5: BID
A6: 34772 | B6: 2105 | C6: =B6+(B6*F6/365*E6)*1 -> 2226.2342 | D6: =A6+E6 -> 34810 | E6: 38 | F6: 0.5532 | G6: BID
A7: 34778 | B7: 700 | C7: =B7+(B7*F7/365*E7)*1 -> 733.80252 | D7: =A7+E7 -> 34810 | E7: 32 | F7: 0.5508 | G7: BID
A8: 34773 | B8: 1739 | C8: =B8+(B8*F8/365*E8)*1 -> 1836.4488 | D8: =A8+E8 -> 34810 | E8: 37 | F8: 0.5528 | G8: BID
A9: 34767 | B9: 2095 | C9: =B9+(B9*F9/365*E9)*1 -> 2216.1582 | D9: =A9+E9 -> 34810 | E9: 43 | F9: 0.4909 | G9: BID
A10: 34771 | B10: 668 | C10: =B10+(B10*F10/365*E10)*1 -> 707.51339 | D10: =A10+E10 -> 34810 | E10: 39 | F10: 0.5536 | G10: BID
A11: 34775 | B11: 25833.04 | C11: =B11+(B11*F11/365*E11)*1 -> 27361.11 | D11: =A11+E11 -> 34814 | E11: 39 | F11: 0.5536 | G11: BID
A12: 34782 | B12: 407 | C12: =B12+(B12*F12/365*E12)*1 -> 426.05708 | D12: =A12+E12 -> 34817 | E12: 35 | F12: 0.4883 | G12: BID
A13: 34787 | B13: 2170 | C13: =B13+(B13*F13/365*E13)*1 -> 2256.8059 | D13: =A13+E13 -> 34817 | E13: 30 | F13: 0.4867 | G13: BID
... A25: 34801 | B25: 2445 | C25: =B25+(B25*F25/365*E25)*1 -> 2542.8067 | D25: =A25+E25 -> 34831 | E25: 30 | F25: 0.4867 | G25: BID
B26: =SUM(B2:B25) -> 114521.26 | C26: =SUM(C2:C25) -> 120211.17
A27: Fecha | B27: Depositado | C27: A Cobrar | D27: Fecha Vto. | E27: Dias | F27: Tasa
A28: 34837 | B28: 10000 | C28: =B28+(B28*F28/365*E28)*1 -> 10198.904 | D28: =A28+E28 -> 34870 | E28: 33 | F28: 0.22 | G28: MERCANTIL
A29: 34837 | B29: 10000 | C29: =B29+(B29*F29/365*E29)*1 -> 10198.904 | D29: =A29+E29 -> 34870 | E29: 33 | F29: 0.22 | G29: MERCANTIL
A30: 34841 | B30: 9000 | C30: =B30+(B30*F30/365*E30)*1 -> 9103.5616 | D30: =A30+E30 -> 34871 | E30: 30 | F30: 0.14 | G30: BNL
A31: 34841 | B31: 8494.94 | C31: =B31+(B31*F31/365*E31)*1 -> 8592.69 | D31: =A31+E31 -> 34871 | E31: 30 | F31: 0.14 | G31: BNL
A32: 34841 | B32: 10000 | C32: =B32+(B32*F32/365*E32)*1 -> 10156.164 | D32: =A32+E32 -> 34871 | E32: 30 | F32: 0.19 | G32: MERCANTIL
A33: 34841 | B33: 10000 | C33: =B33+(B33*F33/365*E33)*1 -> 10156.164 | D33: =A33+E33 -> 34871 | E33: 30 | F33: 0.19 | G33: MERCANTIL
A34: 34837 | B34: 10000 | C34: =B34+(B34*F34/365*E34)*1 -> 10240.46 | D34: =A34+E34 -> 34873 | E34: 36 | F34: 0.2438 | G34: SUDECOR
A35: 34843 | B35: 10000 | C35: =B35+(B35*F35/365*E35)*1 -> 10189.041 | D35: =A35+E35 -> 34873 | E35: 30 | F35: 0.23 | G35: BUEN AYRE
A36: 34837 | B36: 10000 | C36: =B36+(B36*F36/365*E36)*1 -> 10240.46 | D36: =A36+E36 -> 34873 | E36: 36 | F36: 0.2438 | G36: SUDECOR
A37: 34843 | B37: 39960 | C37: =B37+(B37*F37/365*E37)*1 -> 40584.033 | D37: =A37+E37 -> 34873 | E37: 30 | F37: 0.19 | G37: MERCANTIL
A38: 34843 | B38: 20000 | C38: =B38+(B38*F38/365*E38)*1 -> 20515.068 | D38: =A38+E38 -> 34883 | E38: 40 | F38: 0.235 | G38: BUEN AYRE
A39: 34851 | B39: 7179 | C39: =B39+(B39*F39/365*E39)*1 -> 7336.3479 | D39: =A39+E39 -> 34891 | E39: 40 | F39: 0.2 | G39: BUEN AYRE
... A119: 35125 | B119: 2500 | C119: =B119+(B119*F119/365*E119)*1 -> 2532.8767 | D119: =A119+E119 -> 35165 | E119: 40 | F119: 0.12 | G119: SUDECOR
A120: 35116 | B120: =44324.49+2000 -> 46324.49 | C120: =B120+(B120*F120/365*E120)*1 -> 46946.38 | D120: =A120+E120 -> 35165 | E120: 49 | F120: 0.1 | G120: MERCANTIL
A121: 35123 | B121: 16336.92 | C121: =B121+(B121*F121/365*E121)*1 -> 16562.504 | D121: =A121+E121 -> 35165 | E121: 42 | F121: 0.12 | G121: SUDECOR
A122: 35123 | B122: 6650 | C122: =B122+(B122*F122/365*E122)*1 -> 6734.8103 | D122: =A122+E122 -> 35172 | E122: 49 | F122: 0.095 | G122: MERCANTIL
A123: 35123 | B123: 40506.3 | C123: =B123+(B123*F123/365*E123)*1 -> 41022.894 | D123: =A123+E123 -> 35172 | E123: 49 | F123: 0.095 | G123: MERCANTIL
A124: 35129 | B124: 3300 | C124: =B124+(B124*F124/365*E124)*1 -> 3336.9329 | D124: =A124+E124 -> 35172 | E124: 43 | F124: 0.095 | G124: MERCANTIL
A125: 35142 | B125: 19900 | C125: =B125+(B125*F125/365*E125)*1 -> 20119.881 | D125: =A125+E125 -> 35179 | E125: 37 | F125: 0.109 | G125: SUDECOR
A126: 35145 | B126: 10000 | C126: =B126+(B126*F126/365*E126)*1 -> 10119.452 | D126: =A126+E126 -> 35185 | E126: 40 | F126: 0.109 | G126: SUDECOR
A127: 35153 | B127: 25000 | C127: =B127+(B127*F127/365*E127)*1 -> 25238.904 | D127: =A127+E127 -> 35185 | E127: 32 | F127: 0.109 | G127: SUDECOR
A128: 35158 | B128: 28810 | C128: =B128+(B128*F128/365*E128)*1 -> 29058.634 | D128: =A128+E128 -> 35193 | E128: 35 | F128: 0.09 | G128: MERCANTIL
A129: 35158 | B129: 6000 | C129: =B129+(B129*F129/365*E129)*1 -> 6036.8219 | D129: =A129+E129 -> 35193 | E129: 35 | F129: 0.064 | G129: BNL
A130: 35165 | B130: 32305.35 | C130: =B130+(B130*F130/365*E130)*1 -> 32641.149 | D130: =A130+E130 -> 35200 | E130: 35 | F130: 0.1084 | G130: SUDECOR
...

Sheet POR BANC
A3: Etiquetas de fila | B3: Suma de ACOBRAR
A4: BBVA BANCO | B4: 6678632.6
A5: BBVA BANCO BARBARA | B5: 4252055.6
A6: BBVA BANCO RAMONA | B6: 4103689.9
A7: BNA BANCO | B7: 4815311
A8: BNA JUBIL. BANCO | B8: 5248067.3
A9: BNA RAMONA | B9: 2615432.3
A10: HSBC BANCO | B10: 31867807
A11: HSBC BANCO MARIA | B11: 7885593
A12: ITAU BANCO | B12: 24822088
A13: Total general | B13: 92288676

Sheet  PF ANTERIORES U$S
A1: Fecha | B1: Depositado | C1: A Cobrar | D1: Dias | E1: Fecha Vto. | F1: Tasa
A3: 39701 | B3: 62768 | C3: =B3+(B3*F3/365*D3)*1 -> 62957.594 | D3: 35 | E3: =A3+D3 -> 39736 | F3: 0.0315 | G3: HSBC | H3: =+A657 -> 37239 | I3: =+B657 -> 15000 | J3: =+C658 -> 714.28571 | K3: =+E657 -> 13865.714 | L3: =+D657 -> 420 | M3: =+G657 -> 0 | N3: =+F657 -> 0 | O3: =+J3-I3 -> -14285.714
A4: 39800 | B4: 180000 | C4: =B4+(B4*F4/365*D4)*1 -> 180536.55 | D4: 34 | E4: =A4+D4 -> 39834 | F4: 0.032 | G4: HSBC | H4: =+A658 -> 37242 | I4: =+B658 -> 20000 | J4: =+C659 -> 952.38095 | K4: =+E658 -> 18627.619 | L4: =+D658 -> 420 | M4: =+G658 -> 0 | N4: =+F658 -> 0 | O4: =+J4-I4 -> -19047.619
A5: 39800 | B5: 80000 | C5: =B5+(B5*F5/365*D5)*1 -> 80238.466 | D5: 34 | E5: =A5+D5 -> 39834 | F5: 0.032 | G5: HSBC | H5: =+A658 -> 37242 | I5: =+B658 -> 20000 | J5: =+C659 -> 952.38095 | K5: =+E658 -> 18627.619 | L5: =+D658 -> 420 | M5: =+G658 -> 0 | N5: =+F658 -> 0 | O5: =+J5-I5 -> -19047.619
A6: 39834 | B6: 180537 | C6: =B6+(B6*F6/365*D6)*1 -> 181056.35 | D6: 35 | E6: =A6+D6 -> 39869 | F6: 0.03 | G6: HSBC | H6: =+A659 -> 37252 | I6: =+B659 -> 20000 | J6: =+C660 -> 952.38095 | K6: =+E659 -> 19047.619 | L6: =+D659 -> 0 | M6: =+G659 -> 0 | N6: =+F659 -> 0 | O6: =+J6-I6 -> -19047.619
A7: 39834 | B7: 80238 | C7: =B7+(B7*F7/365*D7)*1 -> 80468.822 | D7: 35 | E7: =A7+D7 -> 39869 | F7: 0.03 | G7: HSBC | H7: =+A659 -> 37252 | I7: =+B659 -> 20000 | J7: =+C660 -> 952.38095 | K7: =+E659 -> 19047.619 | L7: =+D659 -> 0 | M7: =+G659 -> 0 | N7: =+F659 -> 0 | O7: =+J7-I7 -> -19047.619
A8: 39864 | B8: 135000 | C8: =B8+(B8*F8/365*D8)*1 -> 135274.62 | D8: 33 | E8: =A8+D8 -> 39897 | F8: 0.0225 | G8: HSBC | H8: =+#REF! -> #REF! | I8: =+#REF! -> #REF! | J8: =+#REF! -> #REF! | K8: =+#REF! -> #REF! | L8: =+#REF! -> #REF! | M8: =+#REF! -> #REF! | N8: =+#REF! -> #REF! | O8: =+J8-I8 -> #REF!
A9: 39869 | B9: 181056 | C9: =B9+(B9*F9/365*D9)*1 -> 181472.68 | D9: 35 | E9: =A9+D9 -> 39904 | F9: 0.024 | G9: HSBC | H9: =+#REF! -> #REF! | I9: =+#REF! -> #REF! | J9: =+#REF! -> #REF! | K9: =+#REF! -> #REF! | L9: =+#REF! -> #REF! | M9: =+#REF! -> #REF! | N9: =+#REF! -> #REF! | O9: =+J9-I9 -> #REF!
A10: 39869 | B10: 80469 | C10: =B10+(B10*F10/365*D10)*1 -> 80654.189 | D10: 35 | E10: =A10+D10 -> 39904 | F10: 0.024 | G10: HSBC | H10: =+A659 -> 37252 | I10: =+B659 -> 20000 | J10: =+C660 -> 952.38095 | K10: =+E659 -> 19047.619 | L10: =+D659 -> 0 | M10: =+G659 -> 0 | N10: =+F659 -> 0 | O10: =+J10-I10 -> -19047.619
A11: 39871 | B11: 89300 | C11: =B11+(B11*F11/365*D11)*1 -> 89380.737 | D11: 33 | E11: =A11+D11 -> 39904 | F11: 0.01 | G11: BBVA | H11: =+A659 -> 37252 | I11: =+B659 -> 20000 | J11: =+C660 -> 952.38095 | K11: =+E659 -> 19047.619 | L11: =+D659 -> 0 | M11: =+G659 -> 0 | N11: =+F659 -> 0 | O11: =+J11-I11 -> -19047.619
A12: 39876 | B12: 45000 | C12: =B12+(B12*F12/365*D12)*1 -> 45043.151 | D12: 35 | E12: =A12+D12 -> 39911 | F12: 0.01 | G12: BBVA | H12: =+A659 -> 37252 | I12: =+B659 -> 20000 | J12: =+C660 -> 952.38095 | K12: =+E659 -> 19047.619 | L12: =+D659 -> 0 | M12: =+G659 -> 0 | N12: =+F659 -> 0 | O12: =+J12-I12 -> -19047.619
A13: 39897 | B13: 135275 | C13: =B13+(B13*F13/365*D13)*1 -> 135508.49 | D13: 30 | E13: =A13+D13 -> 39927 | F13: 0.021 | G13: HSBC | H13: =+#REF! -> #REF! | I13: =+#REF! -> #REF! | J13: =+#REF! -> #REF! | K13: =+#REF! -> #REF! | L13: =+#REF! -> #REF! | M13: =+#REF! -> #REF! | N13: =+#REF! -> #REF! | O13: =+J13-I13 -> #REF!
A14: 39904 | B14: 181473 | C14: =B14+(B14*F14/365*D14)*1 -> 181838.43 | D14: 35 | E14: =A14+D14 -> 39939 | F14: 0.021 | G14: HSBC | H14: =+#REF! -> #REF! | I14: =+#REF! -> #REF! | J14: =+#REF! -> #REF! | K14: =+#REF! -> #REF! | L14: =+#REF! -> #REF! | M14: =+#REF! -> #REF! | N14: =+#REF! -> #REF! | O14: =+J14-I14 -> #REF!
A15: 39904 | B15: 80654 | C15: =B15+(B15*F15/365*D15)*1 -> 80816.413 | D15: 35 | E15: =A15+D15 -> 39939 | F15: 0.021 | G15: HSBC | H15: =+A659 -> 37252 | I15: =+B659 -> 20000 | J15: =+C660 -> 952.38095 | K15: =+E659 -> 19047.619 | L15: =+D659 -> 0 | M15: =+G659 -> 0 | N15: =+F659 -> 0 | O15: =+J15-I15 -> -19047.619
A16: 39904 | B16: 89381 | C16: =B16+(B16*F16/365*D16)*1 -> 89560.986 | D16: 35 | E16: =A16+D16 -> 39939 | F16: 0.021 | G16: HSBC | H16: =+A660 -> 37253 | I16: =+B660 -> 20000 | J16: =+C661 -> 952.38095 | K16: =+E660 -> 19047.619 | L16: =+D660 -> 0 | M16: =+G660 -> 0 | N16: =+F660 -> 0 | O16: =+J16-I16 -> -19047.619
A17: 39911 | B17: 45950 | C17: =B17+(B17*F17/365*D17)*1 -> 46038.123 | D17: 35 | E17: =A17+D17 -> 39946 | F17: 0.02 | G17: HSBC | H17: =+CARTERA!#REF! -> #REF! | I17: =+CARTERA!#REF! -> #REF! | J17: =+CARTERA!#REF! -> #REF! | K17: =+CARTERA!#REF! -> #REF! | L17: =+CARTERA!#REF! -> #REF! | M17: =+CARTERA!#REF! -> #REF! | N17: =+CARTERA!#REF! -> #REF! | O17: =+J17-I17 -> #REF!
A18: 39947 | B18: 46038 | C18: =B18+(B18*F18/365*D18)*1 -> 46093.75 | D18: 34 | E18: =A18+D18 -> 39981 | F18: 0.013 | G18: HSBC | H18: =+A660 -> 37253 | I18: =+B660 -> 20000 | J18: =+C661 -> 952.38095 | K18: =+E660 -> 19047.619 | L18: =+D660 -> 0 | M18: =+G660 -> 0 | N18: =+F660 -> 0 | O18: =+J18-I18 -> -19047.619
A19: 39927 | B19: 135508 | C19: =B19+(B19*F19/365*D19)*1 -> 135908.96 | D19: 60 | E19: =A19+D19 -> 39987 | F19: 0.018 | G19: HSBC | H19: =+#REF! -> #REF! | I19: =+#REF! -> #REF! | J19: =+#REF! -> #REF! | K19: =+#REF! -> #REF! | L19: =+#REF! -> #REF! | M19: =+#REF! -> #REF! | N19: =+#REF! -> #REF! | O19: =+J19-I19 -> #REF!
A20: 39940 | B20: 181838 | C20: =B20+(B20*F20/365*D20)*1 -> 182363.09 | D20: 62 | E20: =A20+D20 -> 40002 | F20: 0.017 | G20: HSBC | H20: =+#REF! -> #REF! | I20: =+#REF! -> #REF! | J20: =+#REF! -> #REF! | K20: =+#REF! -> #REF! | L20: =+#REF! -> #REF! | M20: =+#REF! -> #REF! | N20: =+#REF! -> #REF! | O20: =+J20-I20 -> #REF!
A21: 39940 | B21: 80816 | C21: =B21+(B21*F21/365*D21)*1 -> 81049.37 | D21: 62 | E21: =A21+D21 -> 40002 | F21: 0.017 | G21: HSBC | H21: =+A659 -> 37252 | I21: =+B659 -> 20000 | J21: =+C660 -> 952.38095 | K21: =+E659 -> 19047.619 | L21: =+D659 -> 0 | M21: =+G659 -> 0 | N21: =+F659 -> 0 | O21: =+J21-I21 -> -19047.619
A22: 39940 | B22: 89561 | C22: =B22+(B22*F22/365*D22)*1 -> 89819.623 | D22: 62 | E22: =A22+D22 -> 40002 | F22: 0.017 | G22: HSBC | H22: =+A660 -> 37253 | I22: =+B660 -> 20000 | J22: =+C661 -> 952.38095 | K22: =+E660 -> 19047.619 | L22: =+D660 -> 0 | M22: =+G660 -> 0 | N22: =+F660 -> 0 | O22: =+J22-I22 -> -19047.619
A23: 39940 | B23: 27571 | C23: =B23+(B23*F23/365*D23)*1 -> 27650.616 | D23: 62 | E23: =A23+D23 -> 40002 | F23: 0.017 | G23: HSBC | H23: =+A660 -> 37253 | I23: =+B660 -> 20000 | J23: =+C661 -> 952.38095 | K23: =+E660 -> 19047.619 | L23: =+D660 -> 0 | M23: =+G660 -> 0 | N23: =+F660 -> 0 | O23: =+J23-I23 -> -19047.619
A24: 40002 | B24: 81049 | C24: =B24+(B24*F24/365*D24)*1 -> 81128.939 | D24: 30 | E24: =A24+D24 -> 40032 | F24: 0.012 | G24: HSBC | H24: =+#REF! -> #REF! | I24: =+#REF! -> #REF! | J24: =+#REF! -> #REF! | K24: =+#REF! -> #REF! | L24: =+#REF! -> #REF! | M24: =+#REF! -> #REF! | N24: =+#REF! -> #REF! | O24: =+J24-I24 -> #REF!
A25: 40002 | B25: 89820 | C25: =B25+(B25*F25/365*D25)*1 -> 89908.59 | D25: 30 | E25: =A25+D25 -> 40032 | F25: 0.012 | G25: HSBC
A26: 40002 | B26: 182363 | C26: =B26+(B26*F26/365*D26)*1 -> 182789.68 | D26: 61 | E26: =A26+D26 -> 40063 | F26: 0.014 | G26: HSBC
A27: 40002 | B27: 27651 | C27: =B27+(B27*F27/365*D27)*1 -> 27715.696 | D27: 61 | E27: =A27+D27 -> 40063 | F27: 0.014 | G27: HSBC
A28: 39994 | B28: 135909 | C28: =B28+(B28*F28/365*D28)*1 -> 136422.85 | D28: 92 | E28: =A28+D28 -> 40086 | F28: 0.015 | G28: HSBC
A29: 40030 | B29: 47571 | C29: =B29+(B29*F29/365*D29)*1 -> 47694.228 | D29: 61 | E29: =A29+D29 -> 40091 | F29: 0.0155 | G29: HSBC
A30: 40030 | B30: 12493 | C30: =B30+(B30*F30/365*D30)*1 -> 12525.362 | D30: 61 | E30: =A30+D30 -> 40091 | F30: 0.0155 | G30: HSBC
A31: 40032 | B31: 81129 | C31: =B31+(B31*F31/365*D31)*1 -> 81298.482 | D31: 61 | E31: =A31+D31 -> 40093 | F31: 0.0125 | G31: HSBC
A32: 40032 | B32: 89909 | C32: =B32+(B32*F32/365*D32)*1 -> 90096.824 | D32: 61 | E32: =A32+D32 -> 40093 | F32: 0.0125 | G32: HSBC
A33: 40087 | B33: 136423 | C33: =B33+(B33*F33/365*D33)*1 -> 136527.65 | D33: 35 | E33: =A33+D33 -> 40122 | F33: 0.008 | G33: HSBC
A34: 40063 | B34: 182790 | C34: =B34+(B34*F34/365*D34)*1 -> 183442.03 | D34: 93 | E34: =A34+D34 -> 40156 | F34: 0.014 | G34: HSBC
A35: 40063 | B35: 27716 | C35: =B35+(B35*F35/365*D35)*1 -> 27814.866 | D35: 93 | E35: =A35+D35 -> 40156 | F35: 0.014 | G35: HSBC
A36: 40122 | B36: 136528 | C36: =B36+(B36*F36/365*D36)*1 -> 136604.31 | D36: 34 | E36: =A36+D36 -> 40156 | F36: 0.006 | G36: HSBC | H36: =+C37-B37 -> 7726.9176
B37: =SUM(B4:B36) -> 3377016 | C37: =SUM(C4:C36) -> 3384742.9
A38: 40093 | B38: 47694 | C38: =B38+(B38*F38/365*D38)*1 -> 47836.69 | D38: 91 | E38: =A38+D38 -> 40184 | F38: 0.012 | G38: HSBC
A39: 40093 | B39: 12525 | C39: =B39+(B39*F39/365*D39)*1 -> 12562.472 | D39: 91 | E39: =A39+D39 -> 40184 | F39: =+F38 -> 0.012 | G39: HSBC
A40: 40156 | B40: 27815 | C40: =B40+(B40*F40/365*D40)*1 -> 27848.607 | D40: 63 | E40: =A40+D40 -> 40219 | F40: 0.007 | G40: HSBC
A41: 40156 | B41: 136604 | C41: =B41+(B41*F41/365*D41)*1 -> 136769.05 | D41: 63 | E41: =A41+D41 -> 40219 | F41: 0.007 | G41: HSBC
...

Sheet Hoja1
A1: Fecha | B1: Depositado | C1: A Cobrar | D1: Fecha Vto. | E1: Dias | F1: Tasa | G1: titular
A2: 44531 | B2: 90000 | C2: =B2+(B2*F2/365*E2)*1 -> 93010.685 | D2: =+A2+E2 -> 44564 | E2: 33 | F2: 0.37 | G2: HSBC MARIA
A3: 44533 | B3: 28000 | C3: =B3+(B3*F3/365*E3)*1 -> 28879.89 | D3: =+A3+E3 -> 44564 | E3: 31 | F3: 0.37 | G3: CIUDAD
A4: 44533 | B4: 110000 | C4: =B4+(B4*F4/365*E4)*1 -> 113456.71 | D4: =+A4+E4 -> 44564 | E4: 31 | F4: 0.37 | G4: BBVA
A5: 44536 | B5: 31000 | C5: =B5+(B5*F5/365*E5)*1 -> 31942.74 | D5: =+A5+E5 -> 44566 | E5: 30 | F5: 0.37 | G5: CIUDAD
A6: 44536 | B6: 27000 | C6: =B6+(B6*F6/365*E6)*1 -> 27821.096 | D6: =+A6+E6 -> 44566 | E6: 30 | F6: 0.37 | G6: BBVA
A7: 44540 | B7: 8900 | C7: =B7+(B7*F7/365*E7)*1 -> 9179.6795 | D7: =+A7+E7 -> 44571 | E7: 31 | F7: 0.37 | G7: CIUDAD
A8: 44540 | B8: 27000 | C8: =B8+(B8*F8/365*E8)*1 -> 27848.466 | D8: =+A8+E8 -> 44571 | E8: 31 | F8: 0.37 | G8: BBVA
A9: 44543 | B9: 160000 | C9: =B9+(B9*F9/365*E9)*1 -> 164865.75 | D9: =+A9+E9 -> 44573 | E9: 30 | F9: 0.37 | G9: BBVA
A10: 44543 | B10: 51600 | C10: =B10+(B10*F10/365*E10)*1 -> 53169.205 | D10: =+A10+E10 -> 44573 | E10: 30 | F10: 0.37 | G10: CIUDAD
A11: 44545 | B11: 47300 | C11: =B11+(B11*F11/365*E11)*1 -> 48738.438 | D11: =+A11+E11 -> 44575 | E11: 30 | F11: 0.37 | G11: BNA
A12: 44545 | B12: 14000 | C12: =B12+(B12*F12/365*E12)*1 -> 14425.753 | D12: =+A12+E12 -> 44575 | E12: 30 | F12: 0.37 | G12: BBVA
A13: 44546 | B13: 100000 | C13: =B13+(B13*F13/365*E13)*1 -> 103243.84 | D13: =+A13+E13 -> 44578 | E13: 32 | F13: 0.37 | G13: HSBC
... A42: 44564 | B42: 29400 | C42: =B42+(B42*F42/365*E42)*1 -> 30294.082 | D42: =+A42+E42 -> 44594 | E42: 30 | F42: 0.37 | G42: CIUDAD
A43: 44564 | B43: 150000 | C43: =B43+(B43*F43/365*E43)*1 -> 154561.64 | D43: =+A43+E43 -> 44594 | E43: 30 | F43: 0.37 | G43: HSBC MARIA | H43: =SUM(C43:C43) -> 154561.64
A44: 44564 | B44: 18500 | C44: =B44+(B44*F44/365*E44)*1 -> 19062.603 | D44: =+A44+E44 -> 44594 | E44: 30 | F44: 0.37 | G44: BNA | U44: 49314
A45: 44566 | B45: 26900 | C45: =B45+(B45*F45/365*E45)*1 -> 27718.055 | D45: =+A45+E45 -> 44596 | E45: 30 | F45: 0.37 | G45: CIUDAD
A46: 44566 | B46: 25000 | C46: =B46+(B46*F46/365*E46)*1 -> 25760.274 | D46: =+A46+E46 -> 44596 | E46: 30 | F46: 0.37 | G46: BBVA RAMONA
A47: 44573 | B47: 160000 | C47: =B47+(B47*F47/365*E47)*1 -> 165128.77 | D47: =+A47+E47 -> 44603 | E47: 30 | F47: 0.39 | G47: BBVA
A48: 44573 | B48: 53200 | C48: =B48+(B48*F48/365*E48)*1 -> 54905.315 | D48: =+A48+E48 -> 44603 | E48: 30 | F48: 0.39 | G48: CIUDAD
A49: 44574 | B49: 18000 | C49: =B49+(B49*F49/365*E49)*1 -> 18615.452 | D49: =+A49+E49 -> 44606 | E49: 32 | F49: 0.39 | G49: BBVA | U49: 49314
A50: 44574 | B50: 56000 | C50: =B50+(B50*F50/365*E50)*1 -> 57914.74 | D50: =+A50+E50 -> 44606 | E50: 32 | F50: 0.39 | G50: BBVA RAMONA
A51: 44575 | B51: 5000 | C51: =B51+(B51*F51/365*E51)*1 -> 5165.6164 | D51: =+A51+E51 -> 44606 | E51: 31 | F51: 0.39 | G51: HSBC
A52: 44578 | B52: 79700 | C52: =B52+(B52*F52/365*E52)*1 -> 82254.767 | D52: =+A52+E52 -> 44608 | E52: 30 | F52: 0.39 | G52: BBVA BARBARA
A53: 44578 | B53: 124200 | C53: =B53+(B53*F53/365*E53)*1 -> 128181.21 | D53: =+A53+E53 -> 44608 | E53: 30 | F53: 0.39 | G53: BBVA RAMONA | U53: 49314
A54: 44578 | B54: 19100 | C54: =B54+(B54*F54/365*E54)*1 -> 19712.247 | D54: =+A54+E54 -> 44608 | E54: 30 | F54: 0.39 | G54: CIUDAD
A55: 44580 | B55: 61000 | C55: =B55+(B55*F55/365*E55)*1 -> 62955.342 | D55: =+A55+E55 -> 44610 | E55: 30 | F55: 0.39 | G55: BBVA RAMONA | H55: =SUM(C55:C55) -> 62955.342
A56: 44575 | B56: 65000 | C56: =B56+(B56*F56/365*E56)*1 -> 73841.86 | D56: =+A56+E56 -> 44669 | E56: 94 | F56: 0.52819622 | G56: BBVA UVA
A57: 44575 | B57: 48800 | C57: =B57+(B57*F57/365*E57)*1 -> 55167.92 | D57: =+A57+E57 -> 44669 | E57: 94 | F57: 0.50669053 | G57: BNA UVA
A58: 44581 | B58: 120000 | C58: =B58+(B58*F58/365*E58)*1 -> 124103.01 | D58: =+A58+E58 -> 44613 | E58: 32 | F58: 0.39 | G58: HSBC MARIA | H58: =SUM(C58:C58) -> 124103.01
A59: 44581 | B59: 55000 | C59: =B59+(B59*F59/365*E59)*1 -> 56880.548 | D59: =+A59+E59 -> 44613 | E59: 32 | F59: 0.39 | G59: HSBC MARIA
A60: 44585 | B60: 9300 | C60: =B60+(B60*F60/365*E60)*1 -> 9598.1096 | D60: =+A60+E60 -> 44615 | E60: 30 | F60: 0.39 | G60: CIUDAD
A61: 44585 | B61: 54000 | C61: =B61+(B61*F61/365*E61)*1 -> 55730.959 | D61: =+A61+E61 -> 44615 | E61: 30 | F61: 0.39 | G61: BBVA RAMONA
A62: 44585 | B62: 20000 | C62: =B62+(B62*F62/365*E62)*1 -> 20641.096 | D62: =+A62+E62 -> 44615 | E62: 30 | F62: 0.39 | G62: BBVA BARBARA | H62: =SUM(C62:C62) -> 20641.096
A63: 44580 | B63: 159000 | C63: =B63+(B63*F63/365*E63)*1 -> 164096.71 | D63: =+A63+E63 -> 44610 | E63: 30 | F63: 0.39 | G63: BNA | H63: =SUM(C63:C63) -> 164096.71
A64: 44580 | B64: 51000 | C64: =B64+(B64*F64/365*E64)*1 -> 52634.795 | D64: =+A64+E64 -> 44610 | E64: 30 | F64: 0.39 | G64: BBVA
A65: 44587 | B65: 295500 | C65: =B65+(B65*F65/365*E65)*1 -> 304972.19 | D65: =+A65+E65 -> 44617 | E65: 30 | F65: 0.39 | G65: BBVA RAMONA
A66: 44587 | B66: 6600 | C66: =B66+(B66*F66/365*E66)*1 -> 6811.5616 | D66: =+A66+E66 -> 44617 | E66: 30 | F66: 0.39 | G66: BBVA BARBARA
A67: 44585 | B67: 20000 | C67: =B67+(B67*F67/365*E67)*1 -> 20641.096 | D67: =+A67+E67 -> 44615 | E67: 30 | F67: 0.39 | G67: BBVA
A68: 44587 | B68: 52600 | C68: =B68+(B68*F68/365*E68)*1 -> 54286.082 | D68: =+A68+E68 -> 44617 | E68: 30 | F68: 0.39 | G68: CIUDAD
...

Sheet RES.ANT.
A1: descripcion | B1: importe | C1: mes
A2: AUSTRAL | B2: 800 | C2: 35004
A3: AUTO | B3: 250 | C3: 35004
A4: CATAMARCA | B4: 142 | C4: 35004
A5: IMPUESTOS | B5: =1500+1267+896+343 -> 4006 | C5: 35004
A6: NETO | B6: 16009 | C6: 35004
A7: AUTO | B7: =19800-7500-1000 -> 11300 | C7: 35034
A8: IMPUESTOS | B8: 398 | C8: 35034
A9: LAVALLE | B9: 53 | C9: 35034
A10: NETO | B10: =19346-6851 -> 12495 | C10: 35034 | D10: =SUBTOTAL(9,B6:B10) -> 40255
A11: PERSONALES | B11: =520+214 -> 734 | C11: 35034
A12: SAN JUAN | B12: =176+54.52 -> 230.52 | C12: 35034
A13: ALQUILER | B13: -380 | C13: 35065
A14: AUTO | B14: =100+220+46+315 -> 681 | C14: 35065
A15: IMPUESTOS | B15: =54.52+398 -> 452.52 | C15: 35065
A16: LAVALLE | B16: =70+60 -> 130 | C16: 35065
A17: NETO | B17: =18208.778337+555 -> 18763.778 | C17: 35065
A18: PERSONALES | B18: =100+60+150+10+130 -> 450 | C18: 35065
A19: SAN JUAN | B19: =34+40+29+180+24 -> 307 | C19: 35065
A20: ALQUILER | B20: -380 | C20: 35096
A21: AUTO | B21: =130+692 -> 822 | C21: 35096
A22: CATAMARCA | B22: 142 | C22: 35096
A23: IMPUESTOS | B23: =54.52+398 -> 452.52 | C23: 35096
A24: LANDIN | B24: 500 | C24: 35096
A25: LAVALLE | B25: 60 | C25: 35096
A26: NETO | B26: 17498 | C26: 35096
A27: PERSONALES | B27: =150+120+120 -> 390 | C27: 35096
A28: SAN JUAN | B28: =98+166+28 -> 292 | C28: 35096
A29: ALQUILER | B29: -280 | C29: 35125
A30: AUTO | B30: 119 | C30: 35125
A31: CATAMARCA | B31: 0 | C31: 35125
A32: IMPUESTOS | B32: 452.42 | C32: 35125
A33: LANDIN | B33: 0 | C33: 35125
A34: LAVALLE | B34: 120 | C34: 35125
A35: NETO | B35: 23068.549 | C35: 35125
A36: PERSONALES | B36: 555 | C36: 35125
A37: SAN JUAN | B37: 251 | C37: 35125
A38: ALQUILER | B38: -100 | C38: 35156
A39: AUTO | B39: 119 | C39: 35156
A40: CATAMARCA | B40: 142 | C40: 35156
...
